<mujoco model="morphology">
  <option timestep="0.01"/>
  <default>
    <default class="/"/>
    <default class="0/"/>
    <default class="0/1/"/>
    <default class="0/1/2/"/>
    <default class="0/1/3/"/>
    <default class="0/1/3/4/"/>
    <default class="0/1/3/5/"/>
    <default class="0/1/6/"/>
    <default class="0/1/6/7/"/>
    <default class="0/1/6/7/8/"/>
    <default class="0/1/6/7/8/9/"/>
    <default class="0/1/6/7/8/9/10/"/>
  </default>
  <asset>
    <texture name="texplane" type="2d" builtin="checker" rgb1="0.10000000000000001 0.20000000000000001 0.29999999999999999" rgb2="0.20000000000000001 0.29999999999999999 0.40000000000000002" width="300" height="300"/>
    <material name="MatPlane" class="/" texture="texplane" texrepeat="20 20" specular="1.0" shininess="1.0" reflectance="0.5"/>
  </asset>
  <worldbody>
    <light name="//unnamed_light_0" class="/" directional="true" pos="0 0 1.5" dir="0 0 -1.3" cutoff="100.0" exponent="1.0" diffuse="1 1 1" specular="0.10000000000000001 0.10000000000000001 0.10000000000000001"/>
    <geom name="ground" class="/" type="plane" size="15 15 0.5" material="MatPlane" rgba="1 1 1 1"/>
    <geom name="terrain0" class="/" type="box" size="0.066666666666666666 0.25 9.4927636727124769e-05" rgba="0.40000000000000002 0.40000000000000002 0.40000000000000002 1" pos="-4 0 9.4927636727124769e-05"/>
    <geom name="terrain1" class="/" type="box" size="0.066666666666666666 0.25 0.00038126380193443781" rgba="0.40000000000000002 0.40000000000000002 0.40000000000000002 1" pos="-3.8644067796610169 0 0.00038126380193443781"/>
    <geom name="terrain2" class="/" type="box" size="0.066666666666666666 0.25 0.0013651614196386642" rgba="0.40000000000000002 0.40000000000000002 0.40000000000000002 1" pos="-3.7288135593220337 0 0.0013651614196386642"/>
    <geom name="terrain3" class="/" type="box" size="0.066666666666666666 0.25 0.0041325080400187704" rgba="0.40000000000000002 0.40000000000000002 0.40000000000000002 1" pos="-3.593220338983051 0 0.0041325080400187704"/>
    <geom name="terrain4" class="/" type="box" size="0.066666666666666666 0.25 0.010348070802014379" rgba="0.40000000000000002 0.40000000000000002 0.40000000000000002 1" pos="-3.4576271186440679 0 0.010348070802014379"/>
    <geom name="terrain5" class="/" type="box" size="0.066666666666666666 0.25 0.021253802310680227" rgba="0.40000000000000002 0.40000000000000002 0.40000000000000002 1" pos="-3.3220338983050848 0 0.021253802310680227"/>
    <geom name="terrain6" class="/" type="box" size="0.066666666666666666 0.25 0.035705981210384409" rgba="0.40000000000000002 0.40000000000000002 0.40000000000000002 1" pos="-3.1864406779661016 0 0.035705981210384409"/>
    <geom name="terrain7" class="/" type="box" size="0.066666666666666666 0.25 0.049093607162200313" rgba="0.40000000000000002 0.40000000000000002 0.40000000000000002 1" pos="-3.0508474576271185 0 0.049093607162200313"/>
    <geom name="terrain8" class="/" type="box" size="0.066666666666666666 0.25 0.05549637422527242" rgba="0.40000000000000002 0.40000000000000002 0.40000000000000002 1" pos="-2.9152542372881358 0 0.05549637422527242"/>
    <geom name="terrain9" class="/" type="box" size="0.066666666666666666 0.25 0.052249639879623701" rgba="0.40000000000000002 0.40000000000000002 0.40000000000000002 1" pos="-2.7796610169491522 0 0.052249639879623701"/>
    <geom name="terrain10" class="/" type="box" size="0.066666666666666666 0.25 0.042407659015549479" rgba="0.40000000000000002 0.40000000000000002 0.40000000000000002 1" pos="-2.6440677966101696 0 0.042407659015549479"/>
    <geom name="terrain11" class="/" type="box" size="0.066666666666666666 0.25 0.032327138873683207" rgba="0.40000000000000002 0.40000000000000002 0.40000000000000002 1" pos="-2.5084745762711864 0 0.032327138873683207"/>
    <geom name="terrain12" class="/" type="box" size="0.066666666666666666 0.25 0.027156030556583746" rgba="0.40000000000000002 0.40000000000000002 0.40000000000000002 1" pos="-2.3728813559322033 0 0.027156030556583746"/>
    <geom name="terrain13" class="/" type="box" size="0.066666666666666666 0.25 0.028696801412685546" rgba="0.40000000000000002 0.40000000000000002 0.40000000000000002 1" pos="-2.2372881355932206 0 0.028696801412685546"/>
    <geom name="terrain14" class="/" type="box" size="0.066666666666666666 0.25 0.036375258301861668" rgba="0.40000000000000002 0.40000000000000002 0.40000000000000002 1" pos="-2.101694915254237 0 0.036375258301861668"/>
    <geom name="terrain15" class="/" type="box" size="0.066666666666666666 0.25 0.048842951862182425" rgba="0.40000000000000002 0.40000000000000002 0.40000000000000002 1" pos="-1.9661016949152543 0 0.048842951862182425"/>
    <geom name="terrain16" class="/" type="box" size="0.066666666666666666 0.25 0.064389424716469051" rgba="0.40000000000000002 0.40000000000000002 0.40000000000000002 1" pos="-1.8305084745762712 0 0.064389424716469051"/>
    <geom name="terrain17" class="/" type="box" size="0.066666666666666666 0.25 0.08046402939919084" rgba="0.40000000000000002 0.40000000000000002 0.40000000000000002 1" pos="-1.6949152542372881 0 0.08046402939919084"/>
    <geom name="terrain18" class="/" type="box" size="0.066666666666666666 0.25 0.093533788087297981" rgba="0.40000000000000002 0.40000000000000002 0.40000000000000002 1" pos="-1.5593220338983049 0 0.093533788087297981"/>
    <geom name="terrain19" class="/" type="box" size="0.066666666666666666 0.25 0.10000000000000001" rgba="0.40000000000000002 0.40000000000000002 0.40000000000000002 1" pos="-1.4237288135593222 0 0.10000000000000001"/>
    <geom name="terrain20" class="/" type="box" size="0.066666666666666666 0.25 0.097809565702307422" rgba="0.40000000000000002 0.40000000000000002 0.40000000000000002 1" pos="-1.2881355932203391 0 0.097809565702307422"/>
    <geom name="terrain21" class="/" type="box" size="0.066666666666666666 0.25 0.087616953771730607" rgba="0.40000000000000002 0.40000000000000002 0.40000000000000002 1" pos="-1.152542372881356 0 0.087616953771730607"/>
    <geom name="terrain22" class="/" type="box" size="0.066666666666666666 0.25 0.072549328343770147" rgba="0.40000000000000002 0.40000000000000002 0.40000000000000002 1" pos="-1.0169491525423728 0 0.072549328343770147"/>
    <geom name="terrain23" class="/" type="box" size="0.066666666666666666 0.25 0.056689074890898764" rgba="0.40000000000000002 0.40000000000000002 0.40000000000000002 1" pos="-0.8813559322033897 0 0.056689074890898764"/>
    <geom name="terrain24" class="/" type="box" size="0.066666666666666666 0.25 0.043333085316772463" rgba="0.40000000000000002 0.40000000000000002 0.40000000000000002 1" pos="-0.74576271186440657 0 0.043333085316772463"/>
    <geom name="terrain25" class="/" type="box" size="0.066666666666666666 0.25 0.03406761269882691" rgba="0.40000000000000002 0.40000000000000002 0.40000000000000002 1" pos="-0.61016949152542388 0 0.03406761269882691"/>
    <geom name="terrain26" class="/" type="box" size="0.066666666666666666 0.25 0.028898933224964576" rgba="0.40000000000000002 0.40000000000000002 0.40000000000000002 1" pos="-0.47457627118644075 0 0.028898933224964576"/>
    <geom name="terrain27" class="/" type="box" size="0.066666666666666666 0.25 0.02696164446024206" rgba="0.40000000000000002 0.40000000000000002 0.40000000000000002 1" pos="-0.33898305084745761 0 0.02696164446024206"/>
    <geom name="terrain28" class="/" type="box" size="0.066666666666666666 0.25 0.027206838846849036" rgba="0.40000000000000002 0.40000000000000002 0.40000000000000002 1" pos="-0.20338983050847448 0 0.027206838846849036"/>
    <geom name="terrain29" class="/" type="box" size="0.066666666666666666 0.25 0.028776676429642007" rgba="0.40000000000000002 0.40000000000000002 0.40000000000000002 1" pos="-0.067796610169491345 0 0.028776676429642007"/>
    <geom name="terrain30" class="/" type="box" size="0.066666666666666666 0.25 0.031082606671439916" rgba="0.40000000000000002 0.40000000000000002 0.40000000000000002 1" pos="0.067796610169491345 0 0.031082606671439916"/>
    <geom name="terrain31" class="/" type="box" size="0.066666666666666666 0.25 0.033725254869113257" rgba="0.40000000000000002 0.40000000000000002 0.40000000000000002 1" pos="0.20338983050847492 0 0.033725254869113257"/>
    <geom name="terrain32" class="/" type="box" size="0.066666666666666666 0.25 0.036377022308784722" rgba="0.40000000000000002 0.40000000000000002 0.40000000000000002 1" pos="0.33898305084745761 0 0.036377022308784722"/>
    <geom name="terrain33" class="/" type="box" size="0.066666666666666666 0.25 0.03870001158149533" rgba="0.40000000000000002 0.40000000000000002 0.40000000000000002 1" pos="0.4745762711864403 0 0.03870001158149533"/>
    <geom name="terrain34" class="/" type="box" size="0.066666666666666666 0.25 0.040337715520321997" rgba="0.40000000000000002 0.40000000000000002 0.40000000000000002 1" pos="0.61016949152542388 0 0.040337715520321997"/>
    <geom name="terrain35" class="/" type="box" size="0.066666666666666666 0.25 0.040993706476980141" rgba="0.40000000000000002 0.40000000000000002 0.40000000000000002 1" pos="0.74576271186440657 0 0.040993706476980141"/>
    <geom name="terrain36" class="/" type="box" size="0.066666666666666666 0.25 0.040579715305346424" rgba="0.40000000000000002 0.40000000000000002 0.40000000000000002 1" pos="0.88135593220339015 0 0.040579715305346424"/>
    <geom name="terrain37" class="/" type="box" size="0.066666666666666666 0.25 0.039375462848010634" rgba="0.40000000000000002 0.40000000000000002 0.40000000000000002 1" pos="1.0169491525423728 0 0.039375462848010634"/>
    <geom name="terrain38" class="/" type="box" size="0.066666666666666666 0.25 0.038105586810940062" rgba="0.40000000000000002 0.40000000000000002 0.40000000000000002 1" pos="1.1525423728813555 0 0.038105586810940062"/>
    <geom name="terrain39" class="/" type="box" size="0.066666666666666666 0.25 0.037834540424447921" rgba="0.40000000000000002 0.40000000000000002 0.40000000000000002 1" pos="1.2881355932203391 0 0.037834540424447921"/>
    <geom name="terrain40" class="/" type="box" size="0.066666666666666666 0.25 0.039642371073211856" rgba="0.40000000000000002 0.40000000000000002 0.40000000000000002 1" pos="1.4237288135593218 0 0.039642371073211856"/>
    <geom name="terrain41" class="/" type="box" size="0.066666666666666666 0.25 0.044168327453589708" rgba="0.40000000000000002 0.40000000000000002 0.40000000000000002 1" pos="1.5593220338983054 0 0.044168327453589708"/>
    <geom name="terrain42" class="/" type="box" size="0.066666666666666666 0.25 0.05121673670567907" rgba="0.40000000000000002 0.40000000000000002 0.40000000000000002 1" pos="1.6949152542372881 0 0.05121673670567907"/>
    <geom name="terrain43" class="/" type="box" size="0.066666666666666666 0.25 0.059611244966457401" rgba="0.40000000000000002 0.40000000000000002 0.40000000000000002 1" pos="1.8305084745762707 0 0.059611244966457401"/>
    <geom name="terrain44" class="/" type="box" size="0.066666666666666666 0.25 0.067366557316932349" rgba="0.40000000000000002 0.40000000000000002 0.40000000000000002 1" pos="1.9661016949152543 0 0.067366557316932349"/>
    <geom name="terrain45" class="/" type="box" size="0.066666666666666666 0.25 0.072148650848288476" rgba="0.40000000000000002 0.40000000000000002 0.40000000000000002 1" pos="2.101694915254237 0 0.072148650848288476"/>
    <geom name="terrain46" class="/" type="box" size="0.066666666666666666 0.25 0.071968904068011194" rgba="0.40000000000000002 0.40000000000000002 0.40000000000000002 1" pos="2.2372881355932206 0 0.071968904068011194"/>
    <geom name="terrain47" class="/" type="box" size="0.066666666666666666 0.25 0.065971248775560501" rgba="0.40000000000000002 0.40000000000000002 0.40000000000000002 1" pos="2.3728813559322033 0 0.065971248775560501"/>
    <geom name="terrain48" class="/" type="box" size="0.066666666666666666 0.25 0.05495786493449744" rgba="0.40000000000000002 0.40000000000000002 0.40000000000000002 1" pos="2.5084745762711869 0 0.05495786493449744"/>
    <geom name="terrain49" class="/" type="box" size="0.066666666666666666 0.25 0.041224201099281134" rgba="0.40000000000000002 0.40000000000000002 0.40000000000000002 1" pos="2.6440677966101696 0 0.041224201099281134"/>
    <geom name="terrain50" class="/" type="box" size="0.066666666666666666 0.25 0.02763585189592533" rgba="0.40000000000000002 0.40000000000000002 0.40000000000000002 1" pos="2.7796610169491522 0 0.02763585189592533"/>
    <geom name="terrain51" class="/" type="box" size="0.066666666666666666 0.25 0.01646118409724465" rgba="0.40000000000000002 0.40000000000000002 0.40000000000000002 1" pos="2.9152542372881358 0 0.01646118409724465"/>
    <geom name="terrain52" class="/" type="box" size="0.066666666666666666 0.25 0.008673801545571699" rgba="0.40000000000000002 0.40000000000000002 0.40000000000000002 1" pos="3.0508474576271185 0 0.008673801545571699"/>
    <geom name="terrain53" class="/" type="box" size="0.066666666666666666 0.25 0.0040300930573957438" rgba="0.40000000000000002 0.40000000000000002 0.40000000000000002 1" pos="3.1864406779661021 0 0.0040300930573957438"/>
    <geom name="terrain54" class="/" type="box" size="0.066666666666666666 0.25 0.0016472624950169064" rgba="0.40000000000000002 0.40000000000000002 0.40000000000000002 1" pos="3.3220338983050848 0 0.0016472624950169064"/>
    <geom name="terrain55" class="/" type="box" size="0.066666666666666666 0.25 0.00059132529165083084" rgba="0.40000000000000002 0.40000000000000002 0.40000000000000002 1" pos="3.4576271186440675 0 0.00059132529165083084"/>
    <geom name="terrain56" class="/" type="box" size="0.066666666666666666 0.25 0.00018620505128557995" rgba="0.40000000000000002 0.40000000000000002 0.40000000000000002 1" pos="3.593220338983051 0 0.00018620505128557995"/>
    <geom name="terrain57" class="/" type="box" size="0.066666666666666666 0.25 5.1392457154675699e-05" rgba="0.40000000000000002 0.40000000000000002 0.40000000000000002 1" pos="3.7288135593220337 0 5.1392457154675699e-05"/>
    <geom name="terrain58" class="/" type="box" size="0.066666666666666666 0.25 1.2425458455688372e-05" rgba="0.40000000000000002 0.40000000000000002 0.40000000000000002 1" pos="3.8644067796610173 0 1.2425458455688372e-05"/>
    <geom name="terrain59" class="/" type="box" size="0.066666666666666666 0.25 2.6308709446004449e-06" rgba="0.40000000000000002 0.40000000000000002 0.40000000000000002 1" pos="4 0 2.6308709446004449e-06"/>
    <site name="body" class="/" size="9.9999999999999995e-07 9.9999999999999995e-07 9.9999999999999995e-07" pos="0 0 1.489284405708313"/>
    <body pos="0 0 1.489284405708313" name="0/">
      <joint name="0/rootx/" class="/" type="slide" axis="1 0 0" stiffness="0.0" armature="0.0" damping="0.0"/>
      <joint name="0/rootz/" class="/" type="slide" axis="0 0 1" stiffness="0.0" armature="0.0" damping="0.0"/>
      <joint name="0/rooty/" class="/" type="hinge" axis="0 1 0" stiffness="0.0" armature="0.0" damping="0.0"/>
      <geom name="0/geom" class="0/" type="capsule" contype="1" conaffinity="1" condim="3" size="0.057574631855701539" rgba="0.14769734868389828 0.47265997302033613 0.064785972761173038 1" friction="0.59999999999999998 0.10000000000000001 0.10000000000000001" fromto="0 0 0 0.10795725198494988 0 0.29875920607121653"/>
      <site name="0/end0" class="0/" size="0.0050000000000000001" pos="0.10795725198494988 0 0.29875920607121653"/>
      <site name="0/attach1" class="0/" size="9.9999999999999995e-07 9.9999999999999995e-07 9.9999999999999995e-07" pos="0.010103876894059428 0 0.027961310459544905"/>
      <body pos="0.010103876894059428 0 0.027961310459544905" name="0/1/">
        <joint name="0/1/joint/" class="0/" type="hinge" axis="0 1 0" limited="true" stiffness="100.0" range="-36.581196790596209 36.581196790596209" armature="0.2" damping="3.5"/>
        <geom name="0/1/geom" class="0/1/" type="capsule" contype="1" conaffinity="1" condim="3" size="0.056029525816455011" rgba="0.92409438783859355 0.42669969654018847 0.727538311890921 1" friction="0.59999999999999998 0.10000000000000001 0.10000000000000001" fromto="0 0 0 0.51219628905384429 0 -0.68675204724076622"/>
        <site name="0/1/end1" class="0/1/" size="0.0050000000000000001" pos="0.51219628905384429 0 -0.68675204724076622"/>
        <site name="0/1/attach2" class="0/1/" size="9.9999999999999995e-07 9.9999999999999995e-07 9.9999999999999995e-07" pos="0.14381850467422483 0 -0.19283164409210846"/>
        <body pos="0.14381850467422483 0 -0.19283164409210846" name="0/1/2/">
          <geom name="0/1/2/geom" class="0/1/2/" type="capsule" contype="1" conaffinity="1" condim="3" size="0.052884565477771546" rgba="0.266057053091038 0.21383281520856456 0.10436365738060494 1" friction="0.59999999999999998 0.10000000000000001 0.10000000000000001" fromto="0 0 0 0.19563090070035161 0 0.40563656954362504"/>
          <site name="0/1/2/end2" class="0/1/2/" size="0.0050000000000000001" pos="0.19563090070035161 0 0.40563656954362504"/>
        </body>
        <site name="0/1/attach3" class="0/1/" size="9.9999999999999995e-07 9.9999999999999995e-07 9.9999999999999995e-07" pos="0.22714920662157281 0 -0.30456132933849128"/>
        <body pos="0.22714920662157281 0 -0.30456132933849128" name="0/1/3/">
          <joint name="0/1/3/joint/" class="0/1/" type="hinge" axis="0 1 0" limited="true" stiffness="100.0" range="-47.186953738260982 47.186953738260982" armature="0.2" damping="3.5"/>
          <geom name="0/1/3/geom" class="0/1/3/" type="capsule" contype="1" conaffinity="1" condim="3" size="0.050971505547805322" rgba="0.40665515361518634 0.63552749046319268 0.78195858749315583 1" friction="0.59999999999999998 0.10000000000000001 0.10000000000000001" fromto="0 0 0 0.36631799716050506 0 0.41931947553414783"/>
          <site name="0/1/3/end3" class="0/1/3/" size="0.0050000000000000001" pos="0.36631799716050506 0 0.41931947553414783"/>
          <site name="0/1/3/attach4" class="0/1/3/" size="9.9999999999999995e-07 9.9999999999999995e-07 9.9999999999999995e-07" pos="0.30179697421337143 0 0.34546309470428527"/>
          <body pos="0.30179697421337143 0 0.34546309470428527" name="0/1/3/4/">
            <joint name="0/1/3/4/joint/" class="0/1/3/" type="hinge" axis="0 1 0" limited="true" stiffness="100.0" range="-50.583397420538631 50.583397420538631" armature="0.2" damping="3.5"/>
            <geom name="0/1/3/4/geom" class="0/1/3/4/" type="capsule" contype="1" conaffinity="1" condim="3" size="0.065121218784336368" rgba="0.19496503300145185 0.078220100631843814 0.64276795431389955 1" friction="0.59999999999999998 0.10000000000000001 0.10000000000000001" fromto="0 0 0 0.60667182501592554 0 -0.52821207365873546"/>
            <site name="0/1/3/4/end4" class="0/1/3/4/" size="0.0050000000000000001" pos="0.60667182501592554 0 -0.52821207365873546"/>
          </body>
          <site name="0/1/3/attach5" class="0/1/3/" size="9.9999999999999995e-07 9.9999999999999995e-07 9.9999999999999995e-07" pos="0.3644573289125515 0 0.41718959264572109"/>
          <body pos="0.3644573289125515 0 0.41718959264572109" name="0/1/3/5/">
            <joint name="0/1/3/5/joint/" class="0/1/3/" type="hinge" axis="0 1 0" limited="true" stiffness="100.0" range="-65.900030930946087 65.900030930946087" armature="0.2" damping="3.5"/>
            <geom name="0/1/3/5/geom" class="0/1/3/5/" type="capsule" contype="1" conaffinity="1" condim="3" size="0.056225328296337779" rgba="0.95028582852928567 0.69947014441526212 0.25848377334871375 1" friction="0.59999999999999998 0.10000000000000001 0.10000000000000001" fromto="0 0 0 0.25031914703149916 0 0.40205987501383555"/>
            <site name="0/1/3/5/end5" class="0/1/3/5/" size="0.0050000000000000001" pos="0.25031914703149916 0 0.40205987501383555"/>
          </body>
        </body>
        <site name="0/1/attach6" class="0/1/" size="9.9999999999999995e-07 9.9999999999999995e-07 9.9999999999999995e-07" pos="0.36467872393421963 0 -0.48896070822693488"/>
        <body pos="0.36467872393421963 0 -0.48896070822693488" name="0/1/6/">
          <joint name="0/1/6/joint/" class="0/1/" type="hinge" axis="0 1 0" limited="true" stiffness="100.0" range="-58.301433025227794 58.301433025227794" armature="0.2" damping="3.5"/>
          <geom name="0/1/6/geom" class="0/1/6/" type="capsule" contype="1" conaffinity="1" condim="3" size="0.064702436060142976" rgba="0.43873558018374637 0.12056519082988126 0.8885807687800964 1" friction="0.59999999999999998 0.10000000000000001 0.10000000000000001" fromto="0 0 0 -0.48818444735020583 0 -0.11719111321926334"/>
          <site name="0/1/6/end6" class="0/1/6/" size="0.0050000000000000001" pos="-0.48818444735020583 0 -0.11719111321926334"/>
          <site name="0/1/6/attach7" class="0/1/6/" size="9.9999999999999995e-07 9.9999999999999995e-07 9.9999999999999995e-07" pos="-0.46946925487457547 0 -0.1126984378539653"/>
          <body pos="-0.46946925487457547 0 -0.1126984378539653" name="0/1/6/7/">
            <joint name="0/1/6/7/joint/" class="0/1/6/" type="hinge" axis="0 1 0" limited="true" stiffness="100.0" range="-47.20102338475678 47.20102338475678" armature="0.2" damping="3.5"/>
            <geom name="0/1/6/7/geom" class="0/1/6/7/" type="capsule" contype="1" conaffinity="1" condim="3" size="0.058796171864646175" rgba="0.95260629454079004 0.17139085873119519 0.37594150371706347 1" friction="0.59999999999999998 0.10000000000000001 0.10000000000000001" fromto="0 0 0 -0.01293442924970889 0 -0.21105081681483051"/>
            <site name="0/1/6/7/end7" class="0/1/6/7/" size="0.0050000000000000001" pos="-0.01293442924970889 0 -0.21105081681483051"/>
            <site name="0/1/6/7/attach8" class="0/1/6/7/" size="9.9999999999999995e-07 9.9999999999999995e-07 9.9999999999999995e-07" pos="-0.01254242534165597 0 -0.20465449708614697"/>
            <body pos="-0.01254242534165597 0 -0.20465449708614697" name="0/1/6/7/8/">
              <joint name="0/1/6/7/8/joint/" class="0/1/6/7/" type="hinge" axis="0 1 0" limited="true" stiffness="100.0" range="-53.730967405264238 53.730967405264238" armature="0.2" damping="3.5"/>
              <geom name="0/1/6/7/8/geom" class="0/1/6/7/8/" type="capsule" contype="1" conaffinity="1" condim="3" size="0.050194451662341495" rgba="0.31725911542696006 0.6960071599292561 0.51394531642556207 1" friction="0.59999999999999998 0.10000000000000001 0.10000000000000001" fromto="0 0 0 0.046561316166253919 0 -0.45093204002963788"/>
              <site name="0/1/6/7/8/end8" class="0/1/6/7/8/" size="0.0050000000000000001" pos="0.046561316166253919 0 -0.45093204002963788"/>
              <site name="0/1/6/7/8/attach9" class="0/1/6/7/8/" size="9.9999999999999995e-07 9.9999999999999995e-07 9.9999999999999995e-07" pos="0.024344464956091875 0 -0.23576866270023542"/>
              <body pos="0.024344464956091875 0 -0.23576866270023542" name="0/1/6/7/8/9/">
                <geom name="0/1/6/7/8/9/geom" class="0/1/6/7/8/9/" type="capsule" contype="1" conaffinity="1" condim="3" size="0.045784776033602877" rgba="0.48185093929262401 0.83111917210247166 0.29041330809283517 1" friction="0.59999999999999998 0.10000000000000001 0.10000000000000001" fromto="0 0 0 0.24342287547190877 0 0.16547016620854416"/>
                <site name="0/1/6/7/8/9/end9" class="0/1/6/7/8/9/" size="0.0050000000000000001" pos="0.24342287547190877 0 0.16547016620854416"/>
                <site name="0/1/6/7/8/9/attach10" class="0/1/6/7/8/9/" size="9.9999999999999995e-07 9.9999999999999995e-07 9.9999999999999995e-07" pos="0.076085848540509218 0 0.051720439090651799"/>
                <body pos="0.076085848540509218 0 0.051720439090651799" name="0/1/6/7/8/9/10/">
                  <geom name="0/1/6/7/8/9/10/geom" class="0/1/6/7/8/9/10/" type="capsule" contype="1" conaffinity="1" condim="3" size="0.057519018438393542" rgba="0.71117426325270261 0.51883307553235314 0.064365165030811466 1" friction="0.59999999999999998 0.10000000000000001 0.10000000000000001" fromto="0 0 0 0.28238954096539448 0 -0.22971461967872531"/>
                  <site name="0/1/6/7/8/9/10/end10" class="0/1/6/7/8/9/10/" size="0.0050000000000000001" pos="0.28238954096539448 0 -0.22971461967872531"/>
                </body>
              </body>
            </body>
          </body>
        </body>
      </body>
      <camera name="0/side" class="0/" mode="trackcom" pos="0.40000000000000002 -4 0.20000000000000001" quat="0.70699999999999996 0.70699999999999996 0 0"/>
    </body>
  </worldbody>
  <actuator>
    <motor name="0/1/motor" class="0/1/" ctrllimited="true" ctrlrange="-1 1" gear="61" joint="0/1/joint/"/>
    <motor name="0/1/3/motor" class="0/1/3/" ctrllimited="true" ctrlrange="-1 1" gear="65" joint="0/1/3/joint/"/>
    <motor name="0/1/3/4/motor" class="0/1/3/4/" ctrllimited="true" ctrlrange="-1 1" gear="56" joint="0/1/3/4/joint/"/>
    <motor name="0/1/3/5/motor" class="0/1/3/5/" ctrllimited="true" ctrlrange="-1 1" gear="80" joint="0/1/3/5/joint/"/>
    <motor name="0/1/6/motor" class="0/1/6/" ctrllimited="true" ctrlrange="-1 1" gear="66" joint="0/1/6/joint/"/>
    <motor name="0/1/6/7/motor" class="0/1/6/7/" ctrllimited="true" ctrlrange="-1 1" gear="62" joint="0/1/6/7/joint/"/>
    <motor name="0/1/6/7/8/motor" class="0/1/6/7/8/" ctrllimited="true" ctrlrange="-1 1" gear="72" joint="0/1/6/7/8/joint/"/>
  </actuator>
  <sensor>
    <subtreelinvel name="velocity" body="0/"/>
  </sensor>
</mujoco>
